<?xml version="1.0"?>
<robot xmlns:xacro="http://www.ros.org/wiki/xacro" >

    <xacro:include filename="inertial_macros.xacro"/>

    <!-- friction constant -->
    <xacro:property name="friction_constant" value="0.2"/>

    <material name="white">
        <color rgba="1 1 1 1"/>
    </material>

    <material name="orange">
        <color rgba="1 0.3 0.1 1"/>
    </material>

    <material name="blue">
        <color rgba="0.2 0.2 1 1"/>
    </material>

    <material name="black">
        <color rgba="0 0 0 1"/>
    </material>

    <material name="red">
        <color rgba="1 0 0 1"/>
    </material>

<!-- BASE LINK-->
    <link name="base_link">

    </link>

<!-- CHASSIS LINK-->
    <joint name="chassis_joint" type="fixed">
        <parent link="base_link"/>
        <child link="chassis"/>
        <origin xyz="-0.25 0 0"/>
    </joint>

    <link name="chassis">
        <visual>
            <origin xyz="0.6 0 0.25"/>
            <geometry>
                <box size="1.2 0.6 0.5"/>
            </geometry>
            <material name="white"/>
        </visual>
        <collision>
            <origin xyz="0.6 0 0.25"/>
            <geometry>
                <box size="1.2 0.6 0.5"/>
            </geometry>
        </collision>
        <xacro:inertial_box mass="35" x="1.2" y="0.6" z="0.5">
            <origin xyz="0.6 0 0.25" rpy="0 0 0"/>
        </xacro:inertial_box>
    </link>

    <gazebo reference="chassis">
        <material>Gazebo/White</material>
    </gazebo>

<!-- BACK LEFT WHEEL LINK -->
    <joint name="lb_wheel_joint" type="continuous">
        <parent link="base_link"/>
        <child link="lb_wheel"/>
        <origin xyz="0 0.35 0" rpy="-${pi/2} 0 0"/>
        <axis xyz="0 0 1"/>
        <limit effort="1000" velocity="1000"/>
    </joint>

    <link name="lb_wheel">
        <visual>
            <geometry>
                <cylinder radius="0.25" length="0.1"/>
            </geometry>
            <material name="orange"/>
        </visual>
        <collision>
            <geometry>
                <cylinder radius="0.25" length="0.1"/>
            </geometry>
        </collision>
        <xacro:inertial_cylinder mass="2.5" length="0.1" radius="0.25">
            <origin xyz="0 0 0" rpy="0 0 0"/>
        </xacro:inertial_cylinder>
    </link>

    <gazebo reference="lb_wheel">
        <!-- <mu1>${friction_constant}</mu1>
        <mu2>${friction_constant}</mu2> -->
        <material>Gazebo/Orange</material>
    </gazebo>

<!-- BACK RIGHT WHEEL LINK -->
<joint name="rb_wheel_joint" type="continuous">
    <parent link="base_link"/>
    <child link="rb_wheel"/>
    <origin xyz="0 -0.35 0" rpy="${pi/2} 0 0"/>
    <axis xyz="0 0 -1"/>
    <limit effort="1000" velocity="1000"/>
</joint>

<link name="rb_wheel">
    <visual>
        <geometry>
            <cylinder radius="0.25" length="0.1"/>
        </geometry>
        <material name="orange"/>
    </visual>
    <collision>
        <geometry>
            <cylinder radius="0.25" length="0.1"/>
        </geometry>
    </collision>
    <xacro:inertial_cylinder mass="2.5" length="0.1" radius="0.25">
            <origin xyz="0 0 0" rpy="0 0 0"/>
    </xacro:inertial_cylinder>
</link>

<gazebo reference="rb_wheel">
    <!-- <mu1>${friction_constant}</mu1>
    <mu2>${friction_constant}</mu2> -->
    <material>Gazebo/Orange</material>
</gazebo>

<!-- FRONT LEFT WHEEL LINK -->
<joint name="lf_wheel_joint" type="continuous">
    <parent link="base_link"/>
    <child link="lf_wheel"/>
    <origin xyz="0.7 0.35 0" rpy="-${pi/2} 0 0"/>
    <axis xyz="0 0 1"/>
    <limit effort="1000" velocity="1000"/>
</joint>

<link name="lf_wheel">
    <visual>
        <geometry>
            <cylinder radius="0.25" length="0.1"/>
        </geometry>
        <material name="orange"/>
    </visual>
    <collision>
        <geometry>
            <cylinder radius="0.25" length="0.1"/>
        </geometry>
    </collision>
    <xacro:inertial_cylinder mass="2.5" length="0.1" radius="0.25">
            <origin xyz="0 0 0" rpy="0 0 0"/>
    </xacro:inertial_cylinder>
</link>

<gazebo reference="lf_wheel">
    <!-- <mu1>${friction_constant}</mu1>
    <mu2>${friction_constant}</mu2> -->
    <material>Gazebo/Orange</material>
</gazebo>

<!-- FRONT RIGHT WHEEL LINK -->
<joint name="rf_wheel_joint" type="continuous">
    <parent link="base_link"/>
    <child link="rf_wheel"/>
    <origin xyz="0.7 -0.35 0" rpy="${pi/2} 0 0"/>
    <axis xyz="0 0 -1"/>
    <limit effort="1000" velocity="1000"/>
</joint>

<link name="rf_wheel">
    <visual>
        <geometry>
            <cylinder radius="0.25" length="0.1"/>
        </geometry>
        <material name="orange"/>
    </visual>
    <collision>
        <geometry>
            <cylinder radius="0.25" length="0.1"/>
        </geometry>
    </collision>
    <xacro:inertial_cylinder mass="2.5" length="0.1" radius="0.25">
            <origin xyz="0 0 0" rpy="0 0 0"/>
    </xacro:inertial_cylinder>
</link>

<gazebo reference="rf_wheel">
    <!-- <mu1>${friction_constant}</mu1>
    <mu2>${friction_constant}</mu2> -->
    <material>Gazebo/Orange</material>
</gazebo>

</robot>